# JavaScript 错误 - throw、try 和 catch<br>
try 语句测试代码块的错误。<br>
catch 语句处理错误。<br>
throw 语句创建自定义错误。<br>
finally 语句在 try 和 catch 语句之后，无论是否有触发异常，该语句都会执行。<br>
 JavaScript 错误<br>
当 JavaScript 引擎执行 JavaScript 代码时，会发生各种错误。<br>
可能是语法错误，通常是程序员造成的编码错误或错别字。<br>
可能是拼写错误或语言中缺少的功能（可能由于浏览器差异）。<br>
可能是由于来自服务器或用户的错误输出而导致的错误。<br>
当然，也可能是由于许多其他不可预知的因素。<br>
JavaScript 抛出（throw）错误<br>
当错误发生时，当事情出问题时，JavaScript 引擎通常会停止，并生成一个错误消息。<br>
描述这种情况的技术术语是：JavaScript 将抛出一个错误。<br>
JavaScript try 和 catch<br>
try 语句允许我们定义在执行时进行错误测试的代码块。<br>
catch 语句允许我们定义当 try 代码块发生错误时，所执行的代码块。<br>
JavaScript 语句 try 和 catch 是成对出现的。<br>

```
try {
    ...    //异常的抛出
} catch(e) {
    ...    //异常的捕获与处理
} finally {
    ...    //结束处理
}
```
```
function myFunction() {
    var message, x;
    message = document.getElementById("message");
    message.innerHTML = "";
    x = document.getElementById("demo").value;
    try { 
        if(x == "")  throw "值为空";
        if(isNaN(x)) throw "不是数字";
        x = Number(x);
        if(x < 5)    throw "太小";
        if(x > 10)   throw "太大";
    }
    catch(err) {
        message.innerHTML = "错误: " + err;
    }
}
```
